<?xml version="1.0" encoding="utf-8"?>
<!-- This URDF was automatically created by SolidWorks to URDF Exporter! Originally created by Stephen Brawner (brawner@gmail.com) 
     Commit Version: 1.6.0-4-g7f85cfe  Build Version: 1.6.7995.38578
     For more information, please see http://wiki.ros.org/sw_urdf_exporter -->
<robot
  name="humanoid">
  <link
    name="pelvis">
    <inertial>
      <origin
        xyz="-0.05133 0.00 -0.03678"
        rpy="0 0 0" />
      <mass
        value="5.22719" />
      <inertia
        ixx="0.07846"
        ixy="0.00000"
        ixz="0.00576"
        iyy="0.02488"
        iyz="0.00001"
        izz="0.08727" />
    </inertial>
    <visual>
      <origin
        xyz="0 0 0"
        rpy="0 0 0" />
      <geometry>
        <mesh
          filename="../meshes/pelvis.STL" />
      </geometry>
      <material
        name="">
        <color
          rgba="0.752941176470588 0.752941176470588 0.752941176470588 1" />
      </material>
    </visual>
    <collision>
      <origin
        xyz="0 0 0"
        rpy="0 0 0" />
      <geometry>
        <mesh
          filename="../meshes/pelvis.STL" />
      </geometry>
    </collision>
  </link>
  <link
    name="hip_roll_l_link">
    <inertial>
      <origin
        xyz="-0.00048 0.00336 -0.00372"
        rpy="0 0 0" />
      <mass
        value="1.12809" />
      <inertia
        ixx="0.00058"
        ixy="0.00000"
        ixz="0.00000"
        iyy="0.00093"
        iyz="-0.00011"
        izz="0.00108" />
    </inertial>
    <visual>
      <origin
        xyz="0 0 0"
        rpy="0 0 0" />
      <geometry>
        <mesh
          filename="../meshes/hip_roll_l_link.STL" />
      </geometry>
      <material
        name="">
        <color
          rgba="0.752941176470588 0.752941176470588 0.752941176470588 1" />
      </material>
    </visual>
    <collision>
      <origin
        xyz="0 0 0"
        rpy="0 0 0" />
      <geometry>
        <mesh
          filename="../meshes/hip_roll_l_link.STL" />
      </geometry>
    </collision>
  </link>
  <joint
    name="hip_roll_l_joint"
    type="revolute">
    <origin
      xyz="0 0.13 -0.0659230484541305"
      rpy="0 0 0" />
    <parent
      link="pelvis" />
    <child
      link="hip_roll_l_link" />
    <axis
      xyz="1 0 0" />
    <limit effort="150" lower="-0.97" upper="0.97" velocity="12"/>
  </joint>
  <link
    name="hip_yaw_l_link">
    <inertial>
      <origin
        xyz="0.00104 0.00351 0.00968"
        rpy="0 0 0" />
      <mass
        value="1.91605" />
      <inertia
        ixx="0.00237"
        ixy="-0.00005"
        ixz="-0.00001"
        iyy="0.00271"
        iyz="-0.00005"
        izz="0.00152" />
    </inertial>
    <visual>
      <origin
        xyz="0 0 0"
        rpy="0 0 0" />
      <geometry>
        <mesh
          filename="../meshes/hip_yaw_l_link.STL" />
      </geometry>
      <material
        name="">
        <color
          rgba="0.752941176470588 0.752941176470588 0.752941176470588 1" />
      </material>
    </visual>
    <collision>
      <origin
        xyz="0 0 0"
        rpy="0 0 0" />
      <geometry>
        <mesh
          filename="../meshes/hip_yaw_l_link.STL" />
      </geometry>
    </collision>
  </link>
  <joint
    name="hip_yaw_l_joint"
    type="revolute">
    <origin
      xyz="0 0 -0.116"
      rpy="0 0 0" />
    <parent
      link="hip_roll_l_link" />
    <child
      link="hip_yaw_l_link" />
    <axis
      xyz="0 0 1" />
    <limit effort="90" lower="-1.0472" upper="1.0472" velocity="14"/>
  </joint>
  <link
    name="hip_pitch_l_link">
    <inertial>
      <origin
        xyz="0.00823 -0.00853 -0.13551"
        rpy="0 0 0" />
      <mass
        value="3.37311" />
      <inertia
        ixx="0.02261"
        ixy="0.00036"
        ixz="-0.00020"
        iyy="0.02274"
        iyz="-0.00132"
        izz="0.00637" />
    </inertial>
    <visual>
      <origin
        xyz="0 0 0"
        rpy="0 0 0" />
      <geometry>
        <mesh
          filename="../meshes/hip_pitch_l_link.STL" />
      </geometry>
      <material
        name="">
        <color
          rgba="0.752941176470588 0.752941176470588 0.752941176470588 1" />
      </material>
    </visual>
    <collision>
      <origin
        xyz="0 0 0"
        rpy="0 0 0" />
      <geometry>
        <mesh
          filename="../meshes/hip_pitch_l_link.STL" />
      </geometry>
    </collision>
  </link>
  <joint
    name="hip_pitch_l_joint"
    type="revolute">
    <origin
      xyz="0 0 0"
      rpy="0 0 0" />
    <parent
      link="hip_yaw_l_link" />
    <child
      link="hip_pitch_l_link" />
    <axis
      xyz="0 1 0" />
    <limit effort="150" lower="-1.57" upper="0.5236" velocity="12"/>
  </joint>
  <link
    name="knee_pitch_l_link">
    <inertial>
      <origin
        xyz="0.00228 0.00293 -0.12066"
        rpy="0 0 0" />
      <mass
        value="2.28832" />
      <inertia
        ixx="0.02033"
        ixy="0.00004"
        ixz="0.00049"
        iyy="0.02013"
        iyz="0.00089"
        izz="0.00090" />
    </inertial>
    <visual>
      <origin
        xyz="0 0 0"
        rpy="0 0 0" />
      <geometry>
        <mesh
          filename="../meshes/knee_pitch_l_link.STL" />
      </geometry>
      <material
        name="">
        <color
          rgba="0.752941176470588 0.752941176470588 0.752941176470588 1" />
      </material>
    </visual>
    <collision>
      <origin
        xyz="0 0 0"
        rpy="0 0 0" />
      <geometry>
        <mesh
          filename="../meshes/knee_pitch_l_link.STL" />
      </geometry>
    </collision>
  </link>
  <joint
    name="knee_pitch_l_joint"
    type="revolute">
    <origin
      xyz="0 0 -0.3"
      rpy="0 0 0" />
    <parent
      link="hip_pitch_l_link" />
    <child
      link="knee_pitch_l_link" />
    <axis
      xyz="0 1 0" />
    <limit effort="150" lower="0.00" upper="2.443" velocity="12"/>
  </joint>
  <link
    name="ankle_pitch_l_link">
    <inertial>
      <origin
        xyz="0.00027 0.00 0.00"
        rpy="0 0 0" />
      <mass
        value="0.15163" />
      <inertia
        ixx="0.00003"
        ixy="0.00000"
        ixz="0.00000"
        iyy="0.00003"
        iyz="0.00000"
        izz="0.00006" />
    </inertial>
    <visual>
      <origin
        xyz="0 0 0"
        rpy="0 0 0" />
      <geometry>
        <mesh
          filename="../meshes/ankle_pitch_l_link.STL" />
      </geometry>
      <material
        name="">
        <color
          rgba="0.752941176470588 0.752941176470588 0.752941176470588 1" />
      </material>
    </visual>
    <collision>
      <origin
        xyz="0 0 0"
        rpy="0 0 0" />
      <geometry>
        <mesh
          filename="../meshes/ankle_pitch_l_link.STL" />
      </geometry>
    </collision>
  </link>
  <joint
    name="ankle_pitch_l_joint"
    type="revolute">
    <origin
      xyz="0 0 -0.3"
      rpy="0 0 0" />
    <parent
      link="knee_pitch_l_link" />
    <child
      link="ankle_pitch_l_link" />
    <axis
      xyz="0 1 0" />
    <limit effort="60" lower="-1.22" upper="0.5236" velocity="7.8"/>
  </joint>
  <link
    name="ankle_roll_l_link">
    <inertial>
      <origin
        xyz="0.00229 0.00000 -0.02723"
        rpy="0 0 0" />
      <mass
        value="0.74118" />
      <inertia
        ixx="0.00085"
        ixy="0.00000"
        ixz="-0.00034"
        iyy="0.00233"
        iyz="0.00000"
        izz="0.00256" />
    </inertial>
    <visual>
      <origin
        xyz="0 0 0"
        rpy="0 0 0" />
      <geometry>
        <mesh
          filename="../meshes/ankle_roll_l_link.STL" />
      </geometry>
      <material
        name="">
        <color
          rgba="0.752941176470588 0.752941176470588 0.752941176470588 1" />
      </material>
    </visual>
    <collision>
      <origin
        xyz="0 0 0"
        rpy="0 0 0" />
      <geometry>
        <mesh
          filename="../meshes/ankle_roll_l_link.STL" />
      </geometry>
    </collision>

  </link>
  <joint
    name="ankle_roll_l_joint"
    type="revolute">
    <origin
      xyz="0 0 0"
      rpy="0 0 0" />
    <parent
      link="ankle_pitch_l_link" />
    <child
      link="ankle_roll_l_link" />
    <axis
      xyz="1 0 0" />
    <limit effort="30" lower="-0.4363" upper="0.4363" velocity="7.8"/>
  </joint>
  <link
    name="hip_roll_r_link">
    <inertial>
      <origin
        xyz="-0.00048 -0.00336 -0.00372"
        rpy="0 0 0" />
      <mass
        value="1.12809" />
      <inertia
        ixx="0.00058"
        ixy="0.00000"
        ixz="0.00000"
        iyy="0.00093"
        iyz="0.00011"
        izz="0.00108" />
    </inertial>
    <visual>
      <origin
        xyz="0 0 0"
        rpy="0 0 0" />
      <geometry>
        <mesh
          filename="../meshes/hip_roll_r_link.STL" />
      </geometry>
      <material
        name="">
        <color
          rgba="0.752941176470588 0.752941176470588 0.752941176470588 1" />
      </material>
    </visual>
    <collision>
      <origin
        xyz="0 0 0"
        rpy="0 0 0" />
      <geometry>
        <mesh
          filename="../meshes/hip_roll_r_link.STL" />
      </geometry>
    </collision>
  </link>
  <joint
    name="hip_roll_r_joint"
    type="revolute">
    <origin
      xyz="0 -0.13 -0.0659230484541306"
      rpy="0 0 0" />
    <parent
      link="pelvis" />
    <child
      link="hip_roll_r_link" />
    <axis
      xyz="1 0 0" />
    <limit effort="150" lower="-0.97" upper="0.97" velocity="12"/>
  </joint>
  <link
    name="hip_yaw_r_link">
    <inertial>
      <origin
        xyz="0.00104 -0.00351 0.00968"
        rpy="0 0 0" />
      <mass
        value="1.91605" />
      <inertia
        ixx="0.00237"
        ixy="0.00005"
        ixz="-0.00001"
        iyy="0.00271"
        iyz="0.00005"
        izz="0.00152" />
    </inertial>
    <visual>
      <origin
        xyz="0 0 0"
        rpy="0 0 0" />
      <geometry>
        <mesh
          filename="../meshes/hip_yaw_r_link.STL" />
      </geometry>
      <material
        name="">
        <color
          rgba="0.752941176470588 0.752941176470588 0.752941176470588 1" />
      </material>
    </visual>
    <collision>
      <origin
        xyz="0 0 0"
        rpy="0 0 0" />
      <geometry>
        <mesh
          filename="../meshes/hip_yaw_r_link.STL" />
      </geometry>
    </collision>
  </link>
  <joint
    name="hip_yaw_r_joint"
    type="revolute">
    <origin
      xyz="0 0 -0.116"
      rpy="0 0 0" />
    <parent
      link="hip_roll_r_link" />
    <child
      link="hip_yaw_r_link" />
    <axis
      xyz="0 0 1" />
    <limit effort="90" lower="-1.0472" upper="1.0472" velocity="14"/>
  </joint>
  <link
    name="hip_pitch_r_link">
    <inertial>
      <origin
        xyz="0.00823 0.00853 -0.13551"
        rpy="0 0 0" />
      <mass
        value="3.37311" />
      <inertia
        ixx="0.02261"
        ixy="-0.00036"
        ixz="-0.00020"
        iyy="0.02274"
        iyz="0.00132"
        izz="0.00637" />
    </inertial>
    <visual>
      <origin
        xyz="0 0 0"
        rpy="0 0 0" />
      <geometry>
        <mesh
          filename="../meshes/hip_pitch_r_link.STL" />
      </geometry>
      <material
        name="">
        <color
          rgba="0.752941176470588 0.752941176470588 0.752941176470588 1" />
      </material>
    </visual>
    <collision>
      <origin
        xyz="0 0 0"
        rpy="0 0 0" />
      <geometry>
        <mesh
          filename="../meshes/hip_pitch_r_link.STL" />
      </geometry>
    </collision>
  </link>
  <joint
    name="hip_pitch_r_joint"
    type="revolute">
    <origin
      xyz="0 0 0"
      rpy="0 0 0" />
    <parent
      link="hip_yaw_r_link" />
    <child
      link="hip_pitch_r_link" />
    <axis
      xyz="0 1 0" />
    <limit effort="150" lower="-1.57" upper="0.5236" velocity="12"/>
  </joint>
  <link
    name="knee_pitch_r_link">
    <inertial>
      <origin
        xyz="0.00228 -0.00293 -0.12066"
        rpy="0 0 0" />
      <mass
        value="2.28832" />
      <inertia
        ixx="0.02033"
        ixy="-0.00004"
        ixz="0.00049"
        iyy="0.02013"
        iyz="-0.00089"
        izz="0.00090" />
    </inertial>
    <visual>
      <origin
        xyz="0 0 0"
        rpy="0 0 0" />
      <geometry>
        <mesh
          filename="../meshes/knee_pitch_r_link.STL" />
      </geometry>
      <material
        name="">
        <color
          rgba="0.752941176470588 0.752941176470588 0.752941176470588 1" />
      </material>
    </visual>
    <collision>
      <origin
        xyz="0 0 0"
        rpy="0 0 0" />
      <geometry>
        <mesh
          filename="../meshes/knee_pitch_r_link.STL" />
      </geometry>
    </collision>
  </link>
  <joint
    name="knee_pitch_r_joint"
    type="revolute">
    <origin
      xyz="0 0 -0.3"
      rpy="0 0 0" />
    <parent
      link="hip_pitch_r_link" />
    <child
      link="knee_pitch_r_link" />
    <axis
      xyz="0 1 0" />
    <limit effort="150" lower="0.00" upper="2.443" velocity="12"/>
  </joint>
  <link
    name="ankle_pitch_r_link">
    <inertial>
      <origin
        xyz="0.00027 0.00 0.00"
        rpy="0 0 0" />
      <mass
        value="0.15163" />
      <inertia
        ixx="0.00003"
        ixy="0.00000"
        ixz="0.00000"
        iyy="0.00003"
        iyz="0.00000"
        izz="0.00006" />
    </inertial>
    <visual>
      <origin
        xyz="0 0 0"
        rpy="0 0 0" />
      <geometry>
        <mesh
          filename="../meshes/ankle_pitch_r_link.STL" />
      </geometry>
      <material
        name="">
        <color
          rgba="0.752941176470588 0.752941176470588 0.752941176470588 1" />
      </material>
    </visual>
    <collision>
      <origin
        xyz="0 0 0"
        rpy="0 0 0" />
      <geometry>
        <mesh
          filename="../meshes/ankle_pitch_r_link.STL" />
      </geometry>
    </collision>
  </link>
  <joint
    name="ankle_pitch_r_joint"
    type="revolute">
    <origin
      xyz="0 0 -0.3"
      rpy="0 0 0" />
    <parent
      link="knee_pitch_r_link" />
    <child
      link="ankle_pitch_r_link" />
    <axis
      xyz="0 1 0" />
    <limit effort="60" lower="-1.22" upper="0.5236" velocity="7.8"/>
  </joint>
  <link
    name="ankle_roll_r_link">
    <inertial>
      <origin
        xyz="0.00229 0.00000 -0.02723"
        rpy="0 0 0" />
      <mass
        value="0.74118" />
      <inertia
        ixx="0.00085"
        ixy="0.00000"
        ixz="-0.00034"
        iyy="0.00233"
        iyz="0.00000"
        izz="0.00256"  />
    </inertial>
    <visual>
      <origin
        xyz="0 0 0"
        rpy="0 0 0" />
      <geometry>
        <mesh
          filename="../meshes/ankle_roll_r_link.STL" />
      </geometry>
      <material
        name="">
        <color
          rgba="0.752941176470588 0.752941176470588 0.752941176470588 1" />
      </material>
    </visual>
    <collision>
      <origin
        xyz="0 0 0"
        rpy="0 0 0" />
      <geometry>
        <mesh
          filename="../meshes/ankle_roll_r_link.STL" />
      </geometry>
    </collision>

  </link>
  <joint
    name="ankle_roll_r_joint"
    type="revolute">
    <origin
      xyz="0 0 0"
      rpy="0 0 0" />
    <parent
      link="ankle_pitch_r_link" />
    <child
      link="ankle_roll_r_link" />
    <axis
      xyz="1 0 0" />
    <limit effort="30" lower="-0.4363" upper="0.4363" velocity="7.8"/>
  </joint>
  <link
    name="waist_link">
    <inertial>
      <origin
        xyz="0.0835 0.0 0.27951"
        rpy="0 0 0" />
      <mass
        value="14.41" />
      <inertia
        ixx="0.520867"
        ixy="0.0001413"
        ixz="-0.00082871"
        iyy="0.4829717"
        iyz="0.00025814"
        izz="0.123408" />
    </inertial>
    <visual>
      <origin
        xyz="0 0 0"
        rpy="0 0 0" />
      <geometry>
        <mesh
          filename="../meshes/waist_link.STL" />
      </geometry>
      <material
        name="">
        <color
          rgba="0.752941176470588 0.752941176470588 0.752941176470588 1" />
      </material>
    </visual>

    <collision>
      <origin
        xyz="0 0 0"
        rpy="0 0 0" />
      <geometry>
        <mesh
          filename="../meshes/waist_link.STL" />
      </geometry>
    </collision>
  </link>
  <joint
    name="waist_joint"
    type="fixed">
    <origin
      xyz="-0.024 0 0.0062"
      rpy="0 0 0" />
    <parent
      link="pelvis" />
    <child
      link="waist_link" />
    <axis
      xyz="0 0 1" />
    <limit effort="1000" lower="-3.14" upper="3.14" velocity="100"/>
  </joint>

  <joint name="left_fixed_joint" type="fixed">
    <parent link= "waist_link" />
    <child link = "left_link0" />
    <!-- <origin xyz="0 0.21423 0.45439" rpy="0 1.3083 1.5707963" /> -->
    <origin xyz="0 0.15911 0.42582" rpy="0 1.3083 1.5707963" />
  </joint>

  <link
    name="left_link0">
    <inertial>
      <origin
        xyz="0.000007 -0.000002 -0.015501"
        rpy="0 0 0" />
      <mass
        value="1.036000" />
      <inertia
        ixx="0.000836" ixy="-0.000000" ixz="-0.000000" iyy="0.000835" iyz="-0.000000" izz="0.000658" />
    </inertial>
    <visual>
      <origin
        xyz="0 0 0"
        rpy="0 0 0" />
      <geometry>
        <mesh filename="../meshes/link0.STL" />
      </geometry>
      <material
        name="">
        <color
          rgba="0.752941176470588 0.752941176470588 0.752941176470588 1" />
      </material>
    </visual>
    <collision>
      <origin
        xyz="0 0 0"
        rpy="0 0 0" />
      <geometry>
        <mesh filename="../meshes/link0.STL" />
      </geometry>
    </collision>
  </link>
  <link
    name="shoulder_roll_l_link">
    <inertial>
      <origin
        xyz="0.000000 0.000725 -0.029524"
        rpy="0 0 0" />
      <mass
        value="0.222000" />
      <inertia
        ixx="0.000545" ixy="-0.000000" ixz="-0.000000" iyy="0.000279" iyz="-0.000045" izz="0.000505" />
    </inertial>
    <visual>
      <origin
        xyz="0 0 0"
        rpy="0 0 0" />
      <geometry>
        <mesh filename="../meshes/link1.STL" />
      </geometry>
      <material
        name="">
        <color
          rgba="0.752941176470588 0.752941176470588 0.752941176470588 1" />
      </material>
    </visual>
    <collision>
      <origin
        xyz="0 0 0"
        rpy="0 0 0" />
      <geometry>
        <mesh filename="../meshes/link1.STL" />
      </geometry>
    </collision>
  </link>
  <joint
    name="left_joint1"
    type="revolute">
    <origin
      xyz="0 0 0.0767"
      rpy="0 0 0" />
    <parent
      link="left_link0" />
    <child
      link="shoulder_roll_l_link" />
    <axis
      xyz="0 0 1" />
    <limit lower="-3.14159265358979" upper="0.785398163397448" effort="40" start_stop="82" velocity="3.14159265358979" />
    <property inertia="1.24" damping="0" stiffness="0" offset="0" motor_constant="5.31" ratio="100" protect_max_torque="0" equa_inertia="0" />
  </joint>
  <link
    name="left_link2">
    <inertial>
      <origin
        xyz="0.000000 -0.000473 0.006864"
        rpy="0 0 0" />
      <mass
        value="1.226000" />
      <inertia
        ixx="0.001198" ixy="-0.000000" ixz="-0.000000" iyy="0.001180" iyz="-0.000003" izz="0.000952" />
    </inertial>
    <visual>
      <origin
        xyz="0 0 0"
        rpy="0 0 0" />
      <geometry>
        <mesh filename="../meshes/link2.STL" />
      </geometry>
      <material
        name="">
        <color
          rgba="0.75294 0.75294 0.75294 1" />
      </material>
    </visual>
    <collision>
      <origin
        xyz="0 0 0"
        rpy="0 0 0" />
      <geometry>
        <mesh filename="../meshes/link2.STL" />
      </geometry>
    </collision>
  </link>
  <joint
    name="shoulder_roll_l_joint"
    type="revolute">
    <origin
      xyz="0 0 0.0"
      rpy="1.5707963267948966192313216916398 -1.5707963267948966192313216916398 0" />
    <parent
      link="shoulder_roll_l_link" />
    <child
      link="left_link2" />
    <axis
      xyz="0 0 1" />
    <limit lower="-0.087" upper="1.74532925199433" effort="40" start_stop="82" velocity="3.14159265358979" />
    <property inertia="1.24" damping="0" stiffness="0" offset="0" motor_constant="5.31" ratio="100" protect_max_torque="0" equa_inertia="0" />
  </joint>
  <link
    name="elbow_l_link">
    <inertial>
      <origin
        xyz="0.000247 0.003673 -0.081504"
        rpy="0 0 0" />
      <mass
        value="1.824000" />
      <inertia
        ixx="0.014207" ixy="0.000002" ixz="-0.000016" iyy="0.013974" iyz="-0.000547" izz="0.001323" />
    </inertial>
    <visual>
      <origin
        xyz="0 0 0"
        rpy="0 0 0" />
      <geometry>
        <mesh filename="../meshes/link3.STL" />
      </geometry>
      <material
        name="">
        <color
          rgba="0.752941176470588 0.752941176470588 0.752941176470588 1" />
      </material>
    </visual>
    <collision>
      <origin
        xyz="0 0 0"
        rpy="0 0 0" />
      <geometry>
        <mesh filename="../meshes/link3.STL" />
      </geometry>
    </collision>
  </link>
  <joint
    name="left_joint3"
    type="revolute">
    <origin
      xyz="0 -0.253 0"
      rpy="1.5707963267948966192313216916398 0 0" />
    <parent
      link="left_link2" />
    <child
      link="elbow_l_link" />
    <axis
      xyz="0 0 1" />
    <limit lower="-2.26892802759263" upper="2.26892802759263" effort="22" start_stop="42" velocity="4.18879020478639" />
    <property inertia="0.2" damping="0" stiffness="0" offset="0" motor_constant="4.5" ratio="100" protect_max_torque="0" equa_inertia="0" />
  </joint>
  <link
    name="left_link4">
    <inertial>
      <origin
        xyz="0.002765 -0.020714 0.006089"
        rpy="0 0 0" />
      <mass
        value="0.123000" />
      <inertia
        ixx="0.000241" ixy="0.000004" ixz="0.000002" iyy="0.000211" iyz="-0.000006" izz="0.000125" />
    </inertial>
    <visual>
      <origin
        xyz="0 0 0"
        rpy="0 0 0" />
      <geometry>
        <mesh filename="../meshes/link4.STL" />
      </geometry>
      <material
        name="">
        <color
          rgba="0.75294 0.75294 0.75294 1" />
      </material>
    </visual>
    <collision>
      <origin
        xyz="0 0 0"
        rpy="0 0 0" />
      <geometry>
        <mesh filename="../meshes/link4.STL" />
      </geometry>
    </collision>
  </link>
  <joint
    name="elbow_l_joint"
    type="revolute">
    <origin
      xyz="0 0 0"
      rpy="-1.5707963267948966192313216916398 0 0" />
    <parent
      link="elbow_l_link" />
    <child
      link="left_link4" />
    <axis
      xyz="0 0 1" />
    <limit lower="-2.26892802759263" upper="0.1" effort="22" start_stop="42" velocity="4.18879020478639" />
    <property inertia="0.2" damping="0" stiffness="0" offset="0" motor_constant="4.5" ratio="100" protect_max_torque="0" equa_inertia="0" />
  </joint>
  <link
    name="left_link5">
    <inertial>
      <origin
        xyz="0.000563 0.005092 -0.108798"
        rpy="0 0 0" />
      <mass
        value="1.010000" />
      <inertia
        ixx="0.002286" ixy="0.000027" ixz="-0.000035" iyy="0.002080" iyz="-0.000228" izz="0.000629" />
    </inertial>
    <visual>
      <origin
        xyz="0 0 0"
        rpy="0 0 0" />
      <geometry>
        <mesh filename="../meshes/link5.STL" />
      </geometry>
      <material
        name="">
        <color
          rgba="0.752941176470588 0.752941176470588 0.752941176470588 1" />
      </material>
    </visual>
    <collision>
      <origin
        xyz="0 0 0"
        rpy="0 0 0" />
      <geometry>
        <mesh filename="../meshes/link5.STL" />
      </geometry>
    </collision>
  </link>
  <joint
    name="left_joint5"
    type="revolute">
    <origin
      xyz="0 -0.2355 0"
      rpy="1.5707963267948966192313216916398 0 0" />
    <parent
      link="left_link4" />
    <child
      link="left_link5" />
    <axis
      xyz="0 0 1" />
    <limit lower="-2.26892802759263" upper="2.26892802759263" effort="8" start_stop="15" velocity="3.14159265358979" />
    <property inertia="0.085" damping="0" stiffness="0" offset="0" motor_constant="4.63" ratio="100" protect_max_torque="0" equa_inertia="0" />
  </joint>
  <link
    name="left_link6">
    <inertial>
      <origin
        xyz="0.000000 -0.005048 0.000947"
        rpy="0 0 0" />
      <mass
        value="0.487000" />
      <inertia
        ixx="0.000270" ixy="-0.000000" ixz="-0.000000" iyy="0.000208" iyz="-0.000012" izz="0.000250" />
    </inertial>
    <visual>
      <origin
        xyz="0 0 0"
        rpy="0 0 0" />
      <geometry>
        <mesh filename="../meshes/link6.STL" />
      </geometry>
      <material
        name="">
        <color
          rgba="0.75294 0.75294 0.75294 1" />
      </material>
    </visual>
    <collision>
      <origin
        xyz="0 0 0"
        rpy="0 0 0" />
      <geometry>
        <mesh filename="../meshes/link6.STL" />
      </geometry>
    </collision>
  </link>
  <joint
    name="left_joint6"
    type="revolute">
    <origin
      xyz="0 0 0"
      rpy="-1.5707963267948966192313216916398 -1.5707963267948966192313216916398 0" />
    <parent
      link="left_link5" />
    <child
      link="left_link6" />
    <axis
      xyz="0 0 1" />
    <limit lower="-1.30899693899575" upper="1.30899693899575" effort="8" start_stop="15" velocity="3.14159265358979" />
    <property inertia="0.085" damping="0" stiffness="0" offset="0" motor_constant="4.63" ratio="100" protect_max_torque="0" equa_inertia="0" />
  </joint>
  <link
    name="left_link7">
    <inertial>
      <origin
        xyz="-0.000016 -0.066640 -0.015498"
        rpy="0 0 0" />
      <mass
        value="0.228000" />
      <inertia
        ixx="0.000303" ixy="-0.000000" ixz="-0.000000" iyy="0.000168" iyz="0.000088" izz="0.000265" />
    </inertial>
    <visual>
      <origin
        xyz="0 0 0"
        rpy="0 0 0" />
      <geometry>
        <mesh filename="../meshes/link7.STL" />
      </geometry>
      <material
        name="">
        <color
          rgba="0.75294 0.75294 0.75294 1" />
      </material>
    </visual>
    <collision>
      <origin
        xyz="0 0 0"
        rpy="0 0 0" />
      <geometry>
        <mesh filename="../meshes/link7.STL" />
      </geometry>
    </collision>
  </link>
  <joint
    name="left_joint7"
    type="revolute">
    <origin
      xyz="0 0 0"
      rpy="-1.5707963267948966192313216916398 1.5707963267948966192313216916398 0" />
    <parent
      link="left_link6" />
    <child
      link="left_link7" />
    <axis
      xyz="0 0 1" />
    <limit lower="-1.30899693899575" upper="1.30899693899575" effort="8" start_stop="15" velocity="3.14159265358979" />
    <property inertia="0.085" damping="0" stiffness="0" offset="0" motor_constant="4.63" ratio="100" protect_max_torque="0" equa_inertia="0" />
  </joint>

  <joint name="left_flange" type="fixed">
    <origin rpy="0 -1.5707963267948966192313216916398 0" xyz="0 -0.1115 0"/>
    <parent link="left_link7"/>
    <child link="L_hand_base_link"/>
  </joint>
  <link name="L_hand_base_link">
    <inertial>
      <origin
        xyz="-0.002551 -0.066047 -0.0019357"
        rpy="0 0 0" />
      <mass
        value="0.14143" />
      <inertia
        ixx="0.0001234"
        ixy="2.1995E-06"
        ixz="-1.7694E-06"
        iyy="8.3835E-05"
        iyz="1.5968E-06"
        izz="7.7231E-05" />
    </inertial>
    <visual>
      <origin
        xyz="0 0 0"
        rpy="0 0 0" />
      <geometry>
        <mesh filename="../meshes/L_hand_base_link.STL" />
      </geometry>
      <material name="">
        <color rgba="0.1 0.1 0.1 1" />
      </material>
    </visual>
    <collision>
      <origin
        xyz="0 0 0"
        rpy="0 0 0" />
      <geometry>
        <mesh filename="../meshes/L_hand_base_link.STL" />
      </geometry>
    </collision>
  </link>

  <link name="L_thumb_proximal_base">
    <inertial>
      <origin
        xyz="0.0048817 0.00038782 -0.00722"
        rpy="0 0 0" />
      <mass
        value="0.0018869" />
      <inertia
        ixx="5.5158E-08"
        ixy="-1.1803E-08"
        ixz="-4.6743E-09"
        iyy="8.2164E-08"
        iyz="-1.3521E-09"
        izz="6.7434E-08" />
    </inertial>
    <visual>
      <origin
        xyz="0 0 0"
        rpy="0 0 0" />
      <geometry>
        <mesh filename="../meshes/Link11_L.STL" />
      </geometry>
      <material name="">
        <color rgba="0.1 0.1 0.1 1" />
      </material>
    </visual>
    <collision>
      <origin
        xyz="0 0 0"
        rpy="0 0 0" />
      <geometry>
        <mesh filename="../meshes/Link11_L.STL" />
      </geometry>
    </collision>
  </link>

  <joint
    name="L_thumb_proximal_yaw_joint"
    type="revolute">
    <origin
      xyz="-0.01696 -0.0691 0.02045"
      rpy="1.5708 -1.5708 0" />
    <parent
      link="L_hand_base_link" />
    <child
      link="L_thumb_proximal_base" />
    <axis
      xyz="0 0 1" />
    <limit
      lower="-0.1"
      upper="1.3"
      effort="1"
      velocity="0.5" />
  </joint>

  <link name="L_thumb_proximal">
    <inertial>
      <origin
        xyz="0.021936 -0.01279 -0.0080386"
        rpy="0 0 0" />
      <mass
        value="0.0066101" />
      <inertia
        ixx="1.5693E-06"
        ixy="7.8339E-07"
        ixz="8.5959E-10"
        iyy="1.7356E-06"
        iyz="1.0378E-09"
        izz="2.787E-06" />
    </inertial>
    <visual>
      <origin
        xyz="0 0 0"
        rpy="0 0 0" />
      <geometry>
        <mesh filename="../meshes/Link12_L.STL" />
      </geometry>
      <material name="">
        <color rgba="0.1 0.1 0.1 1" />
      </material>
    </visual>
    <collision>
      <origin
        xyz="0 0 0"
        rpy="0 0 0" />
      <geometry>
        <mesh filename="../meshes/Link12_L.STL" />
      </geometry>
    </collision>
  </link>

  <joint
    name="L_thumb_proximal_pitch_joint"
    type="revolute">
    <origin
      xyz="0.0099867 0.0098242 -0.0089"
      rpy="-1.5708 0 0.16939" />
    <parent
      link="L_thumb_proximal_base" />
    <child
      link="L_thumb_proximal" />
    <axis
      xyz="0 0 -1" />
    <limit
      lower="0.0"
      upper="0.5"
      effort="1"
      velocity="0.5" />
  </joint>

  <link name="L_thumb_intermediate">
    <inertial>
      <origin
        xyz="0.0095531 0.0016282 -0.0072002"
        rpy="0 0 0" />
      <mass
        value="0.0037844" />
      <inertia
        ixx="3.6981E-07"
        ixy="9.8603E-08"
        ixz="-2.8173E-12"
        iyy="3.2395E-07"
        iyz="-2.8028E-12"
        izz="4.6532E-07" />
    </inertial>
    <visual>
      <origin
        xyz="0 0 0"
        rpy="0 0 0" />
      <geometry>
        <mesh filename="../meshes/Link13_L.STL" />
      </geometry>
      <material name="">
        <color rgba="0.1 0.1 0.1 1" />
      </material>
    </visual>
    <collision>
      <origin
        xyz="0 0 0"
        rpy="0 0 0" />
      <geometry>
        <mesh filename="../meshes/Link13_L.STL" />
      </geometry>
    </collision>
  </link>

  <joint
    name="L_thumb_intermediate_joint"
    type="revolute">
    <origin
      xyz="0.04407 -0.034553 -0.0008"
      rpy="0 0 0" />
    <parent
      link="L_thumb_proximal" />
    <child
      link="L_thumb_intermediate" />
    <axis
      xyz="0 0 -1" />
    <limit
      lower="0"
      upper="0.8"
      effort="1"
      velocity="0.5" />
    <mimic 
      joint="L_thumb_proximal_pitch_joint"
      multiplier="1.6"
      offset="0" />
  </joint>

  <link name="L_thumb_distal">
    <inertial>
      <origin
        xyz="0.0092888 -0.004953 -0.0060033"
        rpy="0 0 0" />
      <mass
        value="0.003344" />
      <inertia
        ixx="1.3632E-07"
        ixy="5.6787E-08"
        ixz="-9.1939E-11"
        iyy="1.4052E-07"
        iyz="1.2145E-10"
        izz="2.0026E-07" />
    </inertial>
    <visual>
      <origin
        xyz="0 0 0"
        rpy="0 0 0" />
      <geometry>
        <mesh filename="../meshes/Link14_L.STL" />
      </geometry>
      <material name="">
        <color rgba="0.1 0.1 0.1 1" />
      </material>
    </visual>
    <collision>
      <origin
        xyz="0 0 0"
        rpy="0 0 0" />
      <geometry>
        <mesh filename="../meshes/Link14_L.STL" />
      </geometry>
    </collision>
  </link>

  <joint
    name="L_thumb_distal_joint"
    type="revolute">
    <origin
      xyz="0.020248 -0.010156 -0.0012"
      rpy="0 0 0" />
    <parent
      link="L_thumb_intermediate" />
    <child
      link="L_thumb_distal" />
    <axis
      xyz="0 0 -1" />
    <limit
      lower="0"
      upper="1.2"
      effort="1"
      velocity="0.5" />
    <mimic 
      joint="L_thumb_proximal_pitch_joint"
      multiplier="2.4"
      offset="0" />
  </joint>

  <link name="L_index_proximal">
    <inertial>
      <origin
        xyz="0.0012971 -0.011934 -0.0059998"
        rpy="0 0 0" />
      <mass
        value="0.0042405" />
      <inertia
        ixx="6.6215E-07"
        ixy="1.8442E-08"
        ixz="1.3746E-12"
        iyy="2.1167E-07"
        iyz="-1.4773E-11"
        izz="6.9402E-07" />
    </inertial>
    <visual>
      <origin
        xyz="0 0 0"
        rpy="0 0 0" />
      <geometry>
        <mesh filename="../meshes/Link15_L.STL" />
      </geometry>
      <material name="">
        <color rgba="0.1 0.1 0.1 1" />
      </material>
    </visual>
    <collision>
      <origin
        xyz="0 0 0"
        rpy="0 0 0" />
      <geometry>
        <mesh filename="../meshes/Link15_L.STL" />
      </geometry>
    </collision>
  </link>

  <joint
    name="L_index_proximal_joint"
    type="revolute">
    <origin
      xyz="0.00028533 -0.13653 0.032268"
      rpy="-0.034907 0 0" />
    <parent
      link="L_hand_base_link" />
    <child
      link="L_index_proximal" />
    <axis
      xyz="0 0 -1" />
    <limit
      lower="0"
      upper="1.7"
      effort="1"
      velocity="0.5" />
  </joint>

  <link name="L_index_intermediate">
    <inertial>
      <origin
        xyz="0.0021753 -0.019567 -0.005"
        rpy="0 0 0" />
      <mass
        value="0.0045682" />
      <inertia
        ixx="7.6284E-07"
        ixy="-8.063E-08"
        ixz="3.6797E-13"
        iyy="9.4308E-08"
        iyz="1.5743E-13"
        izz="7.8176E-07" />
    </inertial>
    <visual>
      <origin
        xyz="0 0 0"
        rpy="0 0 0" />
      <geometry>
        <mesh filename="../meshes/Link16_L.STL" />
      </geometry>
      <material name="">
        <color rgba="0.1 0.1 0.1 1" />
      </material>
    </visual>
    <collision>
      <origin
        xyz="0 0 0"
        rpy="0 0 0" />
      <geometry>
        <mesh filename="../meshes/Link16_L.STL" />
      </geometry>
    </collision>
  </link>

  <joint
    name="L_index_intermediate_joint"
    type="revolute">
    <origin
      xyz="-0.0024229 -0.032041 -0.001"
      rpy="0 0 0" />
    <parent
      link="L_index_proximal" />
    <child
      link="L_index_intermediate" />
    <axis
      xyz="0 0 -1" />
    <limit
      lower="0"
      upper="1.7"
      effort="1"
      velocity="0.5" />
    <mimic 
      joint="L_index_proximal_joint"
      multiplier="1"
      offset="0" />
  </joint>


  <link name="L_middle_proximal">
    <inertial>
      <origin
        xyz="0.0012971 -0.011934 -0.0059999"
        rpy="0 0 0" />
      <mass
        value="0.0042405" />
      <inertia
        ixx="6.6215E-07"
        ixy="1.8442E-08"
        ixz="1.2299E-12"
        iyy="2.1167E-07"
        iyz="-1.4484E-11"
        izz="6.9402E-07" />
    </inertial>
    <visual>
      <origin
        xyz="0 0 0"
        rpy="0 0 0" />
      <geometry>
        <mesh filename="../meshes/Link17_L.STL" />
      </geometry>
      <material name="">
        <color rgba="0.1 0.1 0.1 1" />
      </material>
    </visual>
    <collision>
      <origin
        xyz="0 0 0"
        rpy="0 0 0" />
      <geometry>
        <mesh filename="../meshes/Link17_L.STL" />
      </geometry>
    </collision>
  </link>

  <joint
    name="L_middle_proximal_joint"
    type="revolute">
    <origin
      xyz="0.00028533 -0.1371 0.01295"
      rpy="0 0 0" />
    <parent
      link="L_hand_base_link" />
    <child
      link="L_middle_proximal" />
    <axis
      xyz="0 0 -1" />
    <limit
      lower="0"
      upper="1.7"
      effort="1"
      velocity="0.5" />
  </joint>

  <link name="L_middle_intermediate">
    <inertial>
      <origin
        xyz="0.001921 -0.020796 -0.0049999"
        rpy="0 0 0" />
      <mass
        value="0.0050397" />
      <inertia
        ixx="9.5823E-07"
        ixy="-1.1425E-07"
        ixz="-2.4186E-12"
        iyy="1.0646E-07"
        iyz="3.6974E-12"
        izz="9.8385E-07" />
    </inertial>
    <visual>
      <origin
        xyz="0 0 0"
        rpy="0 0 0" />
      <geometry>
        <mesh filename="../meshes/Link18_L.STL" />
      </geometry>
      <material name="">
        <color rgba="0.1 0.1 0.1 1" />
      </material>
    </visual>
    <collision>
      <origin
        xyz="0 0 0"
        rpy="0 0 0" />
      <geometry>
        <mesh filename="../meshes/Link18_L.STL" />
      </geometry>
    </collision>
  </link>
    
  <joint
    name="L_middle_intermediate_joint"
    type="revolute">
    <origin
      xyz="-0.0024229 -0.032041 -0.001"
      rpy="0 0 0" />
    <parent
      link="L_middle_proximal" />
    <child
      link="L_middle_intermediate" />
    <axis
      xyz="0 0 -1" />
    <limit
      lower="0"
      upper="1.7"
      effort="1"
      velocity="0.5" />
    <mimic 
      joint="L_middle_proximal_joint"
      multiplier="1"
      offset="0" />
  </joint>



  <link name="L_ring_proximal">
    <inertial>
      <origin
        xyz="0.0012971 -0.011934 -0.0059999"
        rpy="0 0 0" />
      <mass
        value="0.0042405" />
      <inertia
        ixx="6.6215E-07"
        ixy="1.8442E-08"
        ixz="9.6052E-13"
        iyy="2.1167E-07"
        iyz="-1.4124E-11"
        izz="6.9402E-07" />
    </inertial>
    <visual>
      <origin
        xyz="0 0 0"
        rpy="0 0 0" />
      <geometry>
        <mesh filename="../meshes/Link19_L.STL" />
      </geometry>
      <material name="">
        <color rgba="0.1 0.1 0.1 1" />
      </material>
    </visual>
    <collision>
      <origin
        xyz="0 0 0"
        rpy="0 0 0" />
      <geometry>
        <mesh filename="../meshes/Link19_L.STL" />
      </geometry>
    </collision>
  </link>

  <joint
    name="L_ring_proximal_joint"
    type="revolute">
    <origin
      xyz="0.00028533 -0.13691 -0.0062872"
      rpy="0.05236 0 0" />
    <parent
      link="L_hand_base_link" />
    <child
      link="L_ring_proximal" />
    <axis
      xyz="0 0 -1" />
    <limit
      lower="0"
      upper="1.7"
      effort="1"
      velocity="0.5" />
  </joint>

  <link name="L_ring_intermediate">
    <inertial>
      <origin
        xyz="0.0021753 -0.019567 -0.005"
        rpy="0 0 0" />
      <mass
        value="0.0045682" />
      <inertia
        ixx="7.6285E-07"
        ixy="-8.0631E-08"
        ixz="3.3472E-14"
        iyy="9.4308E-08"
        iyz="-4.4773E-13"
        izz="7.8176E-07" />
    </inertial>
    <visual>
      <origin
        xyz="0 0 0"
        rpy="0 0 0" />
      <geometry>
        <mesh filename="../meshes/Link20_L.STL" />
      </geometry>
      <material name="">
        <color rgba="0.1 0.1 0.1 1" />
      </material>
    </visual>
    <collision>
      <origin
        xyz="0 0 0"
        rpy="0 0 0" />
      <geometry>
        <mesh filename="../meshes/Link20_L.STL" />
      </geometry>
    </collision>
  </link>

  <joint
    name="L_ring_intermediate_joint"
    type="revolute">
    <origin
      xyz="-0.0024229 -0.032041 -0.001"
      rpy="0 0 0" />
    <parent
      link="L_ring_proximal" />
    <child
      link="L_ring_intermediate" />
    <axis
      xyz="0 0 -1" />
    <limit
      lower="0"
      upper="1.7"
      effort="1"
      velocity="0.5" />
    <mimic 
      joint="L_ring_proximal_joint"
      multiplier="1"
      offset="0" />
  </joint>


  <link name="L_pinky_proximal">
    <inertial>
      <origin
        xyz="0.0012971 -0.011934 -0.0059999"
        rpy="0 0 0" />
      <mass
        value="0.0042405" />
      <inertia
        ixx="6.6215E-07"
        ixy="1.8442E-08"
        ixz="1.0279E-12"
        iyy="2.1167E-07"
        iyz="-1.4277E-11"
        izz="6.9402E-07" />
    </inertial>
    <visual>
      <origin
        xyz="0 0 0"
        rpy="0 0 0" />
      <geometry>
        <mesh filename="../meshes/Link21_L.STL" />
      </geometry>
      <material name="">
        <color rgba="0.1 0.1 0.1 1" />
      </material>
    </visual>
    <collision>
      <origin
        xyz="0 0 0"
        rpy="0 0 0" />
      <geometry>
        <mesh filename="../meshes/Link21_L.STL" />
      </geometry>
    </collision>
  </link>

  <joint
    name="L_pinky_proximal_joint"
    type="revolute">
    <origin
      xyz="0.00028533 -0.13571 -0.025488"
      rpy="0.10472 0 0" />
    <parent
      link="L_hand_base_link" />
    <child
      link="L_pinky_proximal" />
    <axis
      xyz="0 0 -1" />
    <limit
      lower="0"
      upper="1.7"
      effort="1"
      velocity="0.5" />
  </joint>

  <link name="L_pinky_intermediate">
    <inertial>
      <origin
        xyz="0.0024788 -0.016208 -0.0050001"
        rpy="0 0 0" />
      <mass
        value="0.0036036" />
      <inertia
        ixx="4.3923E-07"
        ixy="-4.1355E-08"
        ixz="1.2263E-12"
        iyy="7.0315E-08"
        iyz="3.1311E-12"
        izz="4.4881E-07" />
    </inertial>
    <visual>
      <origin
        xyz="0 0 0"
        rpy="0 0 0" />
      <geometry>
        <mesh filename="../meshes/Link22_L.STL" />
      </geometry>
      <material name="">
        <color rgba="0.1 0.1 0.1 1" />
      </material>
    </visual>
    <collision>
      <origin
        xyz="0 0 0"
        rpy="0 0 0" />
      <geometry>
        <mesh filename="../meshes/Link22_L.STL" />
      </geometry>
    </collision>
  </link>

  <joint
    name="L_pinky_intermediate_joint"
    type="revolute">
    <origin
      xyz="-0.0024229 -0.032041 -0.001"
      rpy="0 0 0" />
    <parent
      link="L_pinky_proximal" />
    <child
      link="L_pinky_intermediate" />
    <axis
      xyz="0 0 -1" />
    <limit
      lower="0"
      upper="1.7"
      effort="1"
      velocity="0.5" />
    <mimic 
      joint="L_pinky_proximal_joint"
      multiplier="1"
      offset="0" />
  </joint>

  
  <joint name="right_fixed_joint" type="fixed">
    <parent link= "waist_link" />
    <child link = "right_link0" />
    <origin xyz="0 -0.15911 0.42582" rpy="0 1.3083 -1.5707963" />
  </joint>

  <link
    name="right_link0">
    <inertial>
      <origin
        xyz="0.000007 0.000002 0.015501"
        rpy="0 0 0" />
      <mass
        value="1.036000" />
      <inertia
        ixx="0.000836" ixy="-0.000000" ixz="-0.000000" iyy="0.000835" iyz="-0.000000" izz="0.000658" />
    </inertial>
    <visual>
      <origin
        xyz="0 0 0"
        rpy="0 0 0" />
      <geometry>
        <mesh filename="../meshes/link0.STL" />
      </geometry>
      <material
        name="">
        <color
          rgba="0.752941176470588 0.752941176470588 0.752941176470588 1" />
      </material>
    </visual>
    <collision>
      <origin
        xyz="0 0 0"
        rpy="0 0 0" />
      <geometry>
        <mesh filename="../meshes/link0.STL" />
      </geometry>
    </collision>
  </link>
  <link
    name="shoulder_roll_r_link">
    <inertial>
      <origin
        xyz="0.000000 -0.000725 -0.029524"
        rpy="0 0 0" />
      <mass
        value="0.222000" />
      <inertia
        ixx="0.000545" ixy="-0.000000" ixz="-0.000000" iyy="0.000279" iyz="0.000045" izz="0.000505" />
    </inertial>
    <visual>
      <origin
        xyz="0 0 0"
        rpy="0 0 0" />
      <geometry>
        <mesh filename="../meshes/link1.STL" />
      </geometry>
      <material
        name="">
        <color
          rgba="0.752941176470588 0.752941176470588 0.752941176470588 1" />
      </material>
    </visual>
    <collision>
      <origin
        xyz="0 0 0"
        rpy="0 0 0" />
      <geometry>
        <mesh filename="../meshes/link1.STL" />
      </geometry>
    </collision>
  </link>
  <joint
    name="right_joint1"
    type="revolute">
    <origin
      xyz="0 0 0.0767"
      rpy="0 0 0" />
    <parent
      link="right_link0" />
    <child
      link="shoulder_roll_r_link" />
    <axis
      xyz="0 0 1" />
    <limit lower="-0.785398163397448" upper="3.14159265358979" effort="40" start_stop="82" velocity="3.14159265358979" />
    <property inertia="1.24" damping="0" stiffness="0" offset="0" motor_constant="5.31" ratio="100" protect_max_torque="0" equa_inertia="0" />
  </joint>
  <link
    name="right_link2">
    <inertial>
      <origin
        xyz="0.000000 0.000473 0.006864"
        rpy="0 0 0" />
      <mass
        value="1.226000" />
      <inertia
        ixx="0.001198" ixy="-0.000000" ixz="-0.000000" iyy="0.001180" iyz="0.000003" izz="0.000952" />
    </inertial>
    <visual>
      <origin
        xyz="0 0 0"
        rpy="0 0 3.1415926" />
      <geometry>
        <mesh filename="../meshes/link2.STL" />
      </geometry>
      <material
        name="">
        <color
          rgba="0.75294 0.75294 0.75294 1" />
      </material>
    </visual>
    <collision>
      <origin
        xyz="0 0 0"
        rpy="0 0 3.1415926" />
      <geometry>
        <mesh filename="../meshes/link2.STL" />
      </geometry>
    </collision>
  </link>
  <joint
    name="shoulder_roll_r_joint"
    type="revolute">
    <origin
      xyz="0 0 0.0"
      rpy="-1.5707963267948966192313216916398 -1.5707963267948966192313216916398 0" />
    <parent
      link="shoulder_roll_r_link" />
    <child
      link="right_link2" />
    <axis
      xyz="0 0 1" />
    <limit lower="-1.74532925199433" upper="0.087" effort="40" start_stop="82" velocity="3.14159265358979" />
    <property inertia="1.24" damping="0" stiffness="0" offset="0" motor_constant="5.31" ratio="100" protect_max_torque="0" equa_inertia="0" />
  </joint>
  <link
    name="elbow_r_link">
    <inertial>
      <origin
        xyz="0.000247 -0.003673 -0.081504"
        rpy="0 0 0" />
      <mass
        value="1.824000" />
      <inertia
        ixx="0.014207" ixy="-0.000002" ixz="-0.000016" iyy="0.013974" iyz="0.000547" izz="0.001323" />
    </inertial>
    <visual>
      <origin
        xyz="0 0 0"
        rpy="0 0 0" />
      <geometry>
        <mesh filename="../meshes/link3.STL" />
      </geometry>
      <material
        name="">
        <color
          rgba="0.752941176470588 0.752941176470588 0.752941176470588 1" />
      </material>
    </visual>
    <collision>
      <origin
        xyz="0 0 0"
        rpy="0 0 0" />
      <geometry>
        <mesh filename="../meshes/link3.STL" />
      </geometry>
    </collision>
  </link>
  <joint
    name="right_joint3"
    type="revolute">
    <origin
      xyz="0 0.253 0"
      rpy="-1.5707963267948966192313216916398 0 0" />
    <parent
      link="right_link2" />
    <child
      link="elbow_r_link" />
    <axis
      xyz="0 0 1" />
    <limit lower="-2.26892802759263" upper="2.26892802759263" effort="22" start_stop="42" velocity="4.18879020478639" />
    <property inertia="0.2" damping="0" stiffness="0" offset="0" motor_constant="4.5" ratio="100" protect_max_torque="0" equa_inertia="0" />
  </joint>
  <link
    name="right_link4">
    <inertial>
      <origin
        xyz="0.002765 0.020714 0.006089"
        rpy="0 0 0" />
      <mass
        value="0.123000" />
      <inertia
        ixx="0.000241" ixy="-0.000004" ixz="0.000002" iyy="0.000211" iyz="0.000006" izz="0.000125" />
    </inertial>
    <visual>
      <origin
        xyz="0 0 0"
        rpy="0 0 3.1415926" />
      <geometry>
        <mesh filename="../meshes/link4.STL" />
      </geometry>
      <material
        name="">
        <color
          rgba="0.75294 0.75294 0.75294 1" />
      </material>
    </visual>
    <collision>
      <origin
        xyz="0 0 0"
        rpy="0 0 3.1415926" />
      <geometry>
        <mesh filename="../meshes/link4.STL" />
      </geometry>
    </collision>
  </link>
  <joint
    name="elbow_r_joint"
    type="revolute">
    <origin
      xyz="0 0 0"
      rpy="1.5707963267948966192313216916398 0 0" />
    <parent
      link="elbow_r_link" />
    <child
      link="right_link4" />
    <axis
      xyz="0 0 1" />
    <limit lower="-0.1" upper="2.26892802759263" effort="22" start_stop="42" velocity="4.18879020478639" />
    <property inertia="0.2" damping="0" stiffness="0" offset="0" motor_constant="4.5" ratio="100" protect_max_torque="0" equa_inertia="0" />
  </joint>
  <link
    name="right_link5">
    <inertial>
      <origin
        xyz="0.000563 -0.005092 -0.108798"
        rpy="0 0 0" />
      <mass
        value="1.010000" />
      <inertia
        ixx="0.002286" ixy="0.000027" ixz="-0.000035" iyy="0.002080" iyz="0.000228" izz="0.000629" />
    </inertial>
    <visual>
      <origin
        xyz="0 0 0"
        rpy="0 0 0" />
      <geometry>
        <mesh filename="../meshes/link5.STL" />
      </geometry>
      <material
        name="">
        <color
          rgba="0.752941176470588 0.752941176470588 0.752941176470588 1" />
      </material>
    </visual>
    <collision>
      <origin
        xyz="0 0 0"
        rpy="0 0 0" />
      <geometry>
        <mesh filename="../meshes/link5.STL" />
      </geometry>
    </collision>
  </link>
  <joint
    name="right_joint5"
    type="revolute">
    <origin
      xyz="0 0.2355 0"
      rpy="-1.5707963267948966192313216916398 0 0" />
    <parent
      link="right_link4" />
    <child
      link="right_link5" />
    <axis
      xyz="0 0 1" />
    <limit lower="-2.26892802759263" upper="2.26892802759263" effort="8" start_stop="15" velocity="3.14159265358979" />
    <property inertia="0.085" damping="0" stiffness="0" offset="0" motor_constant="4.63" ratio="100" protect_max_torque="0" equa_inertia="0" />
  </joint>
  <link
    name="right_link6">
    <inertial>
      <origin
        xyz="0.000000 0.005048 0.000947"
        rpy="0 0 0" />
      <mass
        value="0.487000" />
      <inertia
        ixx="0.000270" ixy="-0.000000" ixz="-0.000000" iyy="0.000208" iyz="0.000012" izz="0.000250" />
    </inertial>
    <visual>
      <origin
        xyz="0 0 0"
        rpy="3.1415926 0 0" />
      <geometry>
        <mesh filename="../meshes/link6.STL" />
      </geometry>
      <material
        name="">
        <color
          rgba="0.75294 0.75294 0.75294 1" />
      </material>
    </visual>
    <collision>
      <origin
        xyz="0 0 0"
        rpy="3.1415926 0 0" />
      <geometry>
        <mesh filename="../meshes/link6.STL" />
      </geometry>
    </collision>
  </link>
  <joint
    name="right_joint6"
    type="revolute">
    <origin
      xyz="0 0 0"
      rpy="1.5707963267948966192313216916398 -1.5707963267948966192313216916398 0" />
    <parent
      link="right_link5" />
    <child
      link="right_link6" />
    <axis
      xyz="0 0 1" />
    <limit lower="-1.30899693899575" upper="1.30899693899575" effort="8" start_stop="15" velocity="3.14159265358979" />
    <property inertia="0.085" damping="0" stiffness="0" offset="0" motor_constant="4.63" ratio="100" protect_max_torque="0" equa_inertia="0" />
  </joint>
  <link
    name="right_link7">
    <inertial>
      <origin
        xyz="-0.000016 -0.066640 -0.015498"
        rpy="0 0 0" />
      <mass
        value="0.228000" />
      <inertia
        ixx="0.000303" ixy="-0.000000" ixz="-0.000000" iyy="0.000168" iyz="0.000088" izz="0.000265" />
    </inertial>
    <visual>
      <origin
        xyz="0 0 0"
        rpy="0 0 0" />
      <geometry>
        <mesh filename="../meshes/link7.STL" />
      </geometry>
      <material
        name="">
        <color
          rgba="0.75294 0.75294 0.75294 1" />
      </material>
    </visual>
    <collision>
      <origin
        xyz="0 0 0"
        rpy="0 0 0" />
      <geometry>
        <mesh filename="../meshes/link7.STL" />
      </geometry>
    </collision>
  </link>
  <joint
    name="right_joint7"
    type="revolute">
    <origin
      xyz="0 0 0"
      rpy="1.5707963267948966192313216916398 -1.5707963267948966192313216916398 0" />
    <parent
      link="right_link6" />
    <child
      link="right_link7" />
    <axis
      xyz="0 0 1" />
    <limit lower="-1.30899693899575" upper="1.30899693899575" effort="8" start_stop="15" velocity="3.14159265358979" />
    <property inertia="0.085" damping="0" stiffness="0" offset="0" motor_constant="4.63" ratio="100" protect_max_torque="0" equa_inertia="0" />
  </joint>
  <joint name="right_flange" type="fixed">
    <origin rpy="0 -1.5707963267948966192313216916398 0" xyz="0 -0.1115 0"/>
    <parent link="right_link7"/>
    <child link="R_hand_base_link"/>
  </joint>
      <link name="R_hand_base_link">
    <inertial>
      <origin
        xyz="-0.0025264 -0.066047 0.0019598"
        rpy="0 0 0" />
      <mass
        value="0.14143" />
      <inertia
        ixx="0.00012281"
        ixy="2.1711E-06"
        ixz="1.7709E-06"
        iyy="8.3832E-05"
        iyz="-1.6551E-06"
        izz="7.6663E-05" />
    </inertial>
    <visual>
      <origin
        xyz="0 0 0"
        rpy="0 0 0" />
      <geometry>
        <mesh filename="../meshes/R_hand_base_link.STL" />
      </geometry>
      <material name="">
        <color rgba="0.1 0.1 0.1 1" />
      </material>
    </visual>
    <collision>
      <origin
        xyz="0 0 0"
        rpy="0 0 0" />
      <geometry>
        <mesh filename="../meshes/R_hand_base_link.STL" />
      </geometry>
    </collision>
  </link>

  <link name="R_thumb_proximal_base">
    <inertial>
      <origin
        xyz="-0.0048064 0.0009382 -0.00757"
        rpy="0 0 0" />
      <mass
        value="0.0018869" />
      <inertia
        ixx="5.816E-08"
        ixy="1.4539E-08"
        ixz="4.491E-09"
        iyy="7.9161E-08"
        iyz="-1.8727E-09"
        izz="6.7433E-08" />
    </inertial>
    <visual>
      <origin
        xyz="0 0 0"
        rpy="0 0 0" />
      <geometry>
        <mesh filename="../meshes/Link11_R.STL" />
      </geometry>
      <material name="">
        <color rgba="0.1 0.1 0.1 1" />
      </material>
    </visual>
    <collision>
      <origin
        xyz="0 0 0"
        rpy="0 0 0" />
      <geometry>
        <mesh filename="../meshes/Link11_R.STL" />
      </geometry>
    </collision>
  </link>

  <joint
    name="R_thumb_proximal_yaw_joint"
    type="revolute">
    <origin
      xyz="-0.01696 -0.0691 -0.02045"
      rpy="1.5708 -1.5708 0" />
    <parent
      link="R_hand_base_link" />
    <child
      link="R_thumb_proximal_base" />
    <axis
      xyz="0 0 -1" />
    <limit
      lower="-0.1"
      upper="1.3"
      effort="1"
      velocity="0.5" />
  </joint>

  <link name="R_thumb_proximal">
    <inertial>
      <origin
        xyz="0.021932 0.012785 -0.0080386"
        rpy="0 0 0" />
      <mass
        value="0.0066075" />
      <inertia
        ixx="1.5686E-06"
        ixy="-7.8296E-07"
        ixz="8.9143E-10"
        iyy="1.7353E-06"
        iyz="-1.0191E-09"
        izz="2.786E-06" />
    </inertial>
    <visual>
      <origin
        xyz="0 0 0"
        rpy="0 0 0" />
      <geometry>
        <mesh filename="../meshes/Link12_R.STL" />
      </geometry>
      <material name="">
        <color rgba="0.1 0.1 0.1 1" />
      </material>
    </visual>
    <collision>
      <origin
        xyz="0 0 0"
        rpy="0 0 0" />
      <geometry>
        <mesh filename="../meshes/Link12_R.STL" />
      </geometry>
    </collision>
  </link>

  <joint
    name="R_thumb_proximal_pitch_joint"
    type="revolute">
    <origin
      xyz="-0.0088099 0.010892 -0.00925"
      rpy="1.5708 0 2.8587" />
    <parent
      link="R_thumb_proximal_base" />
    <child
      link="R_thumb_proximal" />
    <axis
      xyz="0 0 1" />
    <limit
      lower="0.0"
      upper="0.5"
      effort="1"
      velocity="0.5" />
  </joint>

  <link name="R_thumb_intermediate">
    <inertial>
      <origin
        xyz="0.0095544 -0.0016282 -0.0071997"
        rpy="0 0 0" />
      <mass
        value="0.0037847" />
      <inertia
        ixx="3.6981E-07"
        ixy="-9.8581E-08"
        ixz="-4.7469E-12"
        iyy="3.2394E-07"
        iyz="1.0939E-12"
        izz="4.6531E-07" />
    </inertial>
    <visual>
      <origin
        xyz="0 0 0"
        rpy="0 0 0" />
      <geometry>
        <mesh filename="../meshes/Link13_R.STL" />
      </geometry>
      <material name="">
        <color rgba="0.1 0.1 0.1 1" />
      </material>
    </visual>
    <collision>
      <origin
        xyz="0 0 0"
        rpy="0 0 0" />
      <geometry>
        <mesh filename="../meshes/Link13_R.STL" />
      </geometry>
    </collision>
  </link>

  <joint
    name="R_thumb_intermediate_joint"
    type="revolute">
    <origin
      xyz="0.04407 0.034553 -0.0008"
      rpy="0 0 0" />
    <parent
      link="R_thumb_proximal" />
    <child
      link="R_thumb_intermediate" />
    <axis
      xyz="0 0 1" />
    <limit
      lower="0"
      upper="0.8"
      effort="1"
      velocity="0.5" />
    <mimic 
      joint="R_thumb_proximal_pitch_joint"
      multiplier="1.6"
      offset="0" />
  </joint>

  <link name="R_thumb_distal">
    <inertial>
      <origin
        xyz="0.0092888 0.0049529 -0.0060033"
        rpy="0 0 0" />
      <mass
        value="0.0033441" />
      <inertia
        ixx="1.3632E-07"
        ixy="-5.6788E-08"
        ixz="-9.2764E-11"
        iyy="1.4052E-07"
        iyz="-1.2283E-10"
        izz="2.0026E-07" />
    </inertial>
    <visual>
      <origin
        xyz="0 0 0"
        rpy="0 0 0" />
      <geometry>
        <mesh filename="../meshes/Link14_R.STL" />
      </geometry>
      <material name="">
        <color rgba="0.1 0.1 0.1 1" />
      </material>
    </visual>
    <collision>
      <origin
        xyz="0 0 0"
        rpy="0 0 0" />
      <geometry>
        <mesh filename="../meshes/Link14_R.STL" />
      </geometry>
    </collision>
  </link>

  <joint
    name="R_thumb_distal_joint"
    type="revolute">
    <origin
      xyz="0.020248 0.010156 -0.0012"
      rpy="0 0 0" />
    <parent
      link="R_thumb_intermediate" />
    <child
      link="R_thumb_distal" />
    <axis
      xyz="0 0 1" />
    <limit
      lower="0"
      upper="1.2"
      effort="1"
      velocity="0.5" />
    <mimic 
      joint="R_thumb_proximal_pitch_joint"
      multiplier="2.4"
      offset="0" />
  </joint>


  <link name="R_index_proximal">
    <inertial>
      <origin
        xyz="0.0012259 0.011942 -0.0060001"
        rpy="0 0 0" />
      <mass
        value="0.0042403" />
      <inertia
        ixx="6.6232E-07"
        ixy="-1.5775E-08"
        ixz="1.8515E-12"
        iyy="2.1146E-07"
        iyz="-5.0828E-12"
        izz="6.9398E-07" />
    </inertial>
    <visual>
      <origin
        xyz="0 0 0"
        rpy="0 0 0" />
      <geometry>
        <mesh filename="../meshes/Link15_R.STL" />
      </geometry>
      <material name="">
        <color rgba="0.1 0.1 0.1 1" />
      </material>
    </visual>
    <collision>
      <origin
        xyz="0 0 0"
        rpy="0 0 0" />
      <geometry>
        <mesh filename="../meshes/Link15_R.STL" />
      </geometry>
    </collision>
  </link>

  <joint
    name="R_index_proximal_joint"
    type="revolute">
    <origin
      xyz="0.00028533 -0.13653 -0.032268"
      rpy="-3.1067 0 0" />
    <parent
      link="R_hand_base_link" />
    <child
      link="R_index_proximal" />
    <axis
      xyz="0 0 1" />
    <limit
      lower="0"
      upper="1.7"
      effort="1"
      velocity="0.5" />
  </joint>

  <link name="R_index_intermediate">
    <inertial>
      <origin
        xyz="0.0019697 0.019589 -0.005"
        rpy="0 0 0" />
      <mass
        value="0.0045683" />
      <inertia
        ixx="7.6111E-07"
        ixy="8.7637E-08"
        ixz="-3.7751E-13"
        iyy="9.6076E-08"
        iyz="9.9444E-13"
        izz="7.8179E-07" />
    </inertial>
    <visual>
      <origin
        xyz="0 0 0"
        rpy="0 0 0" />
      <geometry>
        <mesh filename="../meshes/Link16_R.STL" />
      </geometry>
      <material name="">
        <color rgba="0.1 0.1 0.1 1" />
      </material>
    </visual>
    <collision>
      <origin
        xyz="0 0 0"
        rpy="0 0 0" />
      <geometry>
        <mesh filename="../meshes/Link16_R.STL" />
      </geometry>
    </collision>
  </link>

  <joint
    name="R_index_intermediate_joint"
    type="revolute">
    <origin
      xyz="-0.0026138 0.032026 -0.001"
      rpy="0 0 0" />
    <parent
      link="R_index_proximal" />
    <child
      link="R_index_intermediate" />
    <axis
      xyz="0 0 1" />
    <limit
      lower="0"
      upper="1.7"
      effort="1"
      velocity="0.5" />
    <mimic 
      joint="R_index_proximal_joint"
      multiplier="1"
      offset="0" />
  </joint>


  <link name="R_middle_proximal">
    <inertial>
      <origin
        xyz="0.001297 0.011934 -0.0060001"
        rpy="0 0 0" />
      <mass
        value="0.0042403" />
      <inertia
        ixx="6.6211E-07"
        ixy="-1.8461E-08"
        ixz="1.8002E-12"
        iyy="2.1167E-07"
        iyz="-6.6808E-12"
        izz="6.9397E-07" />
    </inertial>
    <visual>
      <origin
        xyz="0 0 0"
        rpy="0 0 0" />
      <geometry>
        <mesh filename="../meshes/Link17_R.STL" />
      </geometry>
      <material name="">
        <color rgba="0.1 0.1 0.1 1" />
      </material>
    </visual>
    <collision>
      <origin
        xyz="0 0 0"
        rpy="0 0 0" />
      <geometry>
        <mesh filename="../meshes/Link17_R.STL" />
      </geometry>
    </collision>
  </link>

  <joint
    name="R_middle_proximal_joint"
    type="revolute">
    <origin
      xyz="0.00028533 -0.1371 -0.01295"
      rpy="-3.1416 0 0" />
    <parent
      link="R_hand_base_link" />
    <child
      link="R_middle_proximal" />
    <axis
      xyz="0 0 1" />
    <limit
      lower="0"
      upper="1.7"
      effort="1"
      velocity="0.5" />
  </joint>

  <link name="R_middle_intermediate">
    <inertial>
      <origin
        xyz="0.001921 0.020796 -0.005"
        rpy="0 0 0" />
      <mass
        value="0.0050396" />
      <inertia
        ixx="9.5822E-07"
        ixy="1.1425E-07"
        ixz="-2.4791E-12"
        iyy="1.0646E-07"
        iyz="5.9173E-12"
        izz="9.8384E-07" />
    </inertial>
    <visual>
      <origin
        xyz="0 0 0"
        rpy="0 0 0" />
      <geometry>
        <mesh filename="../meshes/Link18_R.STL" />
      </geometry>
      <material name="">
        <color rgba="0.1 0.1 0.1 1" />
      </material>
    </visual>
    <collision>
      <origin
        xyz="0 0 0"
        rpy="0 0 0" />
      <geometry>
        <mesh filename="../meshes/Link18_R.STL" />
      </geometry>
    </collision>
  </link>

  <joint
    name="R_middle_intermediate_joint"
    type="revolute">
    <origin
      xyz="-0.0024229 0.032041 -0.001"
      rpy="0 0 0" />
    <parent
      link="R_middle_proximal" />
    <child
      link="R_middle_intermediate" />
    <axis
      xyz="0 0 1" />
    <limit
      lower="0"
      upper="1.7"
      effort="1"
      velocity="0.5" />
    <mimic 
      joint="R_middle_proximal_joint"
      multiplier="1"
      offset="0" />
  </joint>


  <link name="R_ring_proximal">
    <inertial>
      <origin
        xyz="0.001297 0.011934 -0.0060002"
        rpy="0 0 0" />
      <mass
        value="0.0042403" />
      <inertia
        ixx="6.6211E-07"
        ixy="-1.8461E-08"
        ixz="1.5793E-12"
        iyy="2.1167E-07"
        iyz="-6.6868E-12"
        izz="6.9397E-07" />
    </inertial>
    <visual>
      <origin
        xyz="0 0 0"
        rpy="0 0 0" />
      <geometry>
        <mesh filename="../meshes/Link19_R.STL" />
      </geometry>
      <material name="">
        <color rgba="0.1 0.1 0.1 1" />
      </material>
    </visual>
    <collision>
      <origin
        xyz="0 0 0"
        rpy="0 0 0" />
      <geometry>
        <mesh filename="../meshes/Link19_R.STL" />
      </geometry>
    </collision>
  </link>

  <joint
    name="R_ring_proximal_joint"
    type="revolute">
    <origin
      xyz="0.00028533 -0.13691 0.0062872"
      rpy="3.0892 0 0" />
    <parent
      link="R_hand_base_link" />
    <child
      link="R_ring_proximal" />
    <axis
      xyz="0 0 1" />
    <limit
      lower="0"
      upper="1.7"
      effort="1"
      velocity="0.5" />
  </joint>

  <link name="R_ring_intermediate">
    <inertial>
      <origin
        xyz="0.0021753 0.019567 -0.005"
        rpy="0 0 0" />
      <mass
        value="0.0045683" />
      <inertia
        ixx="7.6286E-07"
        ixy="8.0635E-08"
        ixz="-6.1562E-13"
        iyy="9.431E-08"
        iyz="5.8619E-13"
        izz="7.8177E-07" />
    </inertial>
    <visual>
      <origin
        xyz="0 0 0"
        rpy="0 0 0" />
      <geometry>
        <mesh filename="../meshes/Link20_R.STL" />
      </geometry>
      <material name="">
        <color rgba="0.1 0.1 0.1 1" />
      </material>
    </visual>
    <collision>
      <origin
        xyz="0 0 0"
        rpy="0 0 0" />
      <geometry>
        <mesh filename="../meshes/Link20_R.STL" />
      </geometry>
    </collision>
  </link>

  <joint
    name="R_ring_intermediate_joint"
    type="revolute">
    <origin
      xyz="-0.0024229 0.032041 -0.001"
      rpy="0 0 0" />
    <parent
      link="R_ring_proximal" />
    <child
      link="R_ring_intermediate" />
    <axis
      xyz="0 0 1" />
    <limit
      lower="0"
      upper="1.7"
      effort="1"
      velocity="0.5" />
    <mimic 
      joint="R_ring_proximal_joint"
      multiplier="1"
      offset="0" />
  </joint>



  <link name="R_pinky_proximal">
    <inertial>
      <origin
        xyz="0.001297 0.011934 -0.0060001"
        rpy="0 0 0" />
      <mass
        value="0.0042403" />
      <inertia
        ixx="6.6211E-07"
        ixy="-1.8461E-08"
        ixz="1.6907E-12"
        iyy="2.1167E-07"
        iyz="-6.9334E-12"
        izz="6.9397E-07" />
    </inertial>
    <visual>
      <origin
        xyz="0 0 0"
        rpy="0 0 0" />
      <geometry>
        <mesh filename="../meshes/Link21_R.STL" />
      </geometry>
      <material name="">
        <color rgba="0.1 0.1 0.1 1" />
      </material>
    </visual>
    <collision>
      <origin
        xyz="0 0 0"
        rpy="0 0 0" />
      <geometry>
        <mesh filename="../meshes/Link21_R.STL" />
      </geometry>
    </collision>
  </link>

  <joint
    name="R_pinky_proximal_joint"
    type="revolute">
    <origin
      xyz="0.00028533 -0.13571 0.025488"
      rpy="3.0369 0 0" />
    <parent
      link="R_hand_base_link" />
    <child
      link="R_pinky_proximal" />
    <axis
      xyz="0 0 1" />
    <limit
      lower="0"
      upper="1.7"
      effort="1"
      velocity="0.5" />
  </joint>

  <link name="R_pinky_intermediate">
    <inertial>
      <origin
        xyz="0.0024748 0.016203 -0.0050031"
        rpy="0 0 0" />
      <mass
        value="0.0035996" />
      <inertia
        ixx="4.3913E-07"
        ixy="4.1418E-08"
        ixz="3.7168E-11"
        iyy="7.0247E-08"
        iyz="5.8613E-11"
        izz="4.4867E-07" />
    </inertial>
    <visual>
      <origin
        xyz="0 0 0"
        rpy="0 0 0" />
      <geometry>
        <mesh filename="../meshes/Link22_R.STL" />
      </geometry>
      <material name="">
        <color rgba="0.1 0.1 0.1 1" />
      </material>
    </visual>
    <collision>
      <origin
        xyz="0 0 0"
        rpy="0 0 0" />
      <geometry>
        <mesh filename="../meshes/Link22_R.STL" />
      </geometry>
    </collision>
  </link>

  <joint
    name="R_pinky_intermediate_joint"
    type="revolute">
    <origin
      xyz="-0.0024229 0.032041 -0.001"
      rpy="0 0 0" />
    <parent
      link="R_pinky_proximal" />
    <child
      link="R_pinky_intermediate" />
    <axis
      xyz="0 0 1" />
    <limit
      lower="0"
      upper="1.7"
      effort="1"
      velocity="0.5" />
    <mimic 
      joint="R_pinky_proximal_joint"
      multiplier="1"
      offset="0" />
  </joint>



</robot>